Workbook

Sheet Assumptions
A1: B2B SaaS PROJECT MANAGEMENT TOOL — PRICING MODEL ASSUMPTIONS
A2: Blue cells = hardcoded inputs you can change | Yellow background = key assumptions
A4: SECTION 1 — UNIT ECONOMICS (COGS & Target Margin)
A5: Assumption | B5: Value | C5: Notes / Formula
A6: COGS per Seat / Month | B6: 4 | C6: Direct infra + support cost per seat per month | Source: internal cost model, June 2026
A7: Target Gross Margin % | B7: 0.75 | C7: Company target gross margin — drives price floor calculation
A8: Billing Cadence | B8: Monthly | C8: Monthly billing assumed throughout; multiply MRR×12 for ARR
A10: Price Floor = COGS ÷ (1 − Target GM%) | B10: =B6/(1-B7) | C10: =$4.00 ÷ (1 − 75%) = $16.00/seat/mo | NO price may go below this floor
A12: SECTION 2 — DEAL SIZE BREAKPOINTS
A13: Deal Size | B13: Seats | C13: Notes
A14: Small Deal | B14: 50 | C14: Typical SMB / startup
A15: Mid Deal | B15: 200 | C15: Growth-stage company
A16: Large Deal | B16: 500 | C16: Enterprise / department-wide rollout
A19: SECTION 3 — USAGE-BASED OVERAGE PARAMETERS
A20: Parameter | B20: Value | C20: Notes
A21: Included API Calls / Seat / Month | B21: 10000 | C21: Free threshold — no charge up to this level
A22: Overage Rate ($ per API call) | B22: 0.02 | C22: Charge per call above the included threshold
A23: P25 Usage (calls/seat/month) | B23: 15000 | C23: Low-usage cohort — 25th percentile scenario
A24: P50 Usage (calls/seat/month) | B24: 25000 | C24: Median-usage cohort — 50th percentile scenario
A25: P75 Usage (calls/seat/month) | B25: 40000 | C25: High-usage cohort — 75th percentile scenario
A29: Source: Internal model inputs provided by user, June 2026 | Model built: 2026-06-10

Sheet Tier Pricing Matrix
A1: TIER PRICING MATRIX — SEAT-BASED | 3 TIERS: STARTER / GROWTH / ENTERPRISE
A2: Black = formula | Blue = hardcoded input | Green = cross-sheet link | All prices per seat / month
A4: SECTION A — PRICE FLOOR DERIVATION | Formula: COGS ÷ (1 − Target GM%)
A5: Metric | B5: Starter | C5: Growth | D5: Enterprise
A6: COGS / Seat / Month | B6: =Assumptions!$B$6 | C6: =Assumptions!$B$6 | D6: =Assumptions!$B$6
A7: Target Gross Margin % | B7: =Assumptions!$B$7 | C7: =Assumptions!$B$7 | D7: =Assumptions!$B$7
A8: Raw Price Floor = COGS ÷ (1−GM%) | B8: =B6/(1-B7) | C8: =C6/(1-C7) | D8: =D6/(1-D7)
A9: Price Floor (rounded to $0.50) | B9: =CEILING(B8,0.5) | C9: =CEILING(C8,0.5) | D9: =CEILING(D8,0.5)
A11: SECTION B — LIST PRICES (must exceed price floor; change blue cells to scenario-test)
A12: Metric | B12: Starter | C12: Growth | D12: Enterprise
A13: List Price / Seat / Month | B13: 18 | C13: 22 | D13: 28
A14: Above floor? (must be TRUE) | B14: =IF(B13>=B9,"YES — OK","!! BELOW FLOOR !!") | C14: =IF(C13>=C9,"YES — OK","!! BELOW FLOOR !!") | D14: =IF(D13>=D9,"YES — OK","!! BELOW FLOOR !!")
A16: SECTION C — TIER UNIT ECONOMICS
A17: Metric | B17: Starter | C17: Growth | D17: Enterprise
A18: List Price / Seat / Month | B18: =B13 | C18: =C13 | D18: =D13
A19: COGS / Seat / Month | B19: =B6 | C19: =C6 | D19: =D6
A20: Gross Profit / Seat / Month | B20: =B18-B19 | C20: =C18-C19 | D20: =D18-D19
A21: Gross Margin % | B21: =B20/B18 | C21: =C20/C18 | D21: =D20/D18
A22: Premium above Floor ($) | B22: =B18-B9 | C22: =C18-C9 | D22: =D18-D9
A23: Premium above Floor (%) | B23: =B21/B9 | C23: =C21/C9 | D23: =D21/D9
A26: SECTION D — DISCOUNT THRESHOLDS | Hard stop = Price Floor
A27: Metric | B27: Starter | C27: Growth | D27: Enterprise
A28: Max Allowable Discount % | B28: =1-(B9/B13) | C28: =1-(C9/C13) | D28: =1-(D9/D13)
A29: Max Discount Amount / Seat | B29: =B13-B9 | C29: =C13-C9 | D29: =D13-D9
A30: Floor / Hard-Stop Price | B30: =B9 | C30: =C9 | D30: =D9

Sheet Deal Economics
A1: DEAL ECONOMICS — MRR / ARR / GROSS PROFIT | 3 TIERS × 3 DEAL SIZES
A2: All list prices and COGS pulled from Tier Pricing Matrix (green links) — update inputs on Assumptions sheet
A4: SECTION A — MRR & ARR BY TIER AND DEAL SIZE
A5: Deal Size | B5: Seats | C5: Starter MRR ($) | D5: Growth MRR ($) | E5: Enterprise MRR ($) | F5: Starter ARR ($) | G5: Growth ARR ($) | H5: Enterprise ARR ($)
A6: Small Deal (50 seats) | B6: =Assumptions!$B$14 | C6: =B6*'Tier Pricing Matrix'!$B$13 | D6: =B6*'Tier Pricing Matrix'!$C$13 | E6: =B6*'Tier Pricing Matrix'!$D$13 | F6: =C6*12 | G6: =D6*12 | H6: =E6*12
A7: Mid Deal (200 seats) | B7: =Assumptions!$B$15 | C7: =B7*'Tier Pricing Matrix'!$B$13 | D7: =B7*'Tier Pricing Matrix'!$C$13 | E7: =B7*'Tier Pricing Matrix'!$D$13 | F7: =C7*12 | G7: =D7*12 | H7: =E7*12
A8: Large Deal (500 seats) | B8: =Assumptions!$B$16 | C8: =B8*'Tier Pricing Matrix'!$B$13 | D8: =B8*'Tier Pricing Matrix'!$C$13 | E8: =B8*'Tier Pricing Matrix'!$D$13 | F8: =C8*12 | G8: =D8*12 | H8: =E8*12
A11: SECTION B — MONTHLY & ANNUAL GROSS PROFIT BY TIER AND DEAL SIZE
A12: Deal Size | B12: Seats | C12: Starter Monthly GP ($) | D12: Growth Monthly GP ($) | E12: Enterprise Monthly GP ($) | F12: Starter Annual GP ($) | G12: Growth Annual GP ($) | H12: Enterprise Annual GP ($)
A13: Small Deal (50 seats) | B13: =Assumptions!$B$14 | C13: =B13*'Tier Pricing Matrix'!$B$20 | D13: =B13*'Tier Pricing Matrix'!$C$20 | E13: =B13*'Tier Pricing Matrix'!$D$20 | F13: =C13*12 | G13: =D13*12 | H13: =E13*12
A14: Mid Deal (200 seats) | B14: =Assumptions!$B$15 | C14: =B14*'Tier Pricing Matrix'!$B$20 | D14: =B14*'Tier Pricing Matrix'!$C$20 | E14: =B14*'Tier Pricing Matrix'!$D$20 | F14: =C14*12 | G14: =D14*12 | H14: =E14*12
A15: Large Deal (500 seats) | B15: =Assumptions!$B$16 | C15: =B15*'Tier Pricing Matrix'!$B$20 | D15: =B15*'Tier Pricing Matrix'!$C$20 | E15: =B15*'Tier Pricing Matrix'!$D$20 | F15: =C15*12 | G15: =D15*12 | H15: =E15*12
A18: SECTION C — GROSS MARGIN % CHECK AT EACH TIER (independent of deal size)
A19: Metric | B19: Starter | C19: Growth | D19: Enterprise
A20: List Price / Seat / Mo | B20: 'Tier Pricing Matrix'!$B$13 | C20: 'Tier Pricing Matrix'!$C$13 | D20: 'Tier Pricing Matrix'!$D$13
A21: COGS / Seat / Mo | B21: 'Tier Pricing Matrix'!$B$6 | C21: 'Tier Pricing Matrix'!$C$6 | D21: 'Tier Pricing Matrix'!$D$6
A22: GP / Seat / Mo | B22: 'Tier Pricing Matrix'!$B$20 | C22: 'Tier Pricing Matrix'!$C$20 | D22: 'Tier Pricing Matrix'!$D$20
A23: Gross Margin % | B23: =B22/B20 | C23: =C22/C20 | D23: =D22/D20

Sheet Expansion Revenue
A1: EXPANSION REVENUE — USAGE-BASED OVERAGE MODEL | P25 / P50 / P75 SCENARIOS
A2: Formula: Overage Rev/Seat/Mo = MAX(0, Usage − Included Threshold) × Overage Rate | Never uses a single average
A4: SECTION A — OVERAGE MECHANICS
A5: Parameter | B5: Value | C5: Formula / Derivation
A6: Included Calls / Seat / Month | B6: =Assumptions!$B$21 | C6: Threshold from Assumptions sheet
A7: Overage Rate ($ / call) | B7: =Assumptions!$B$22 | C7: Rate from Assumptions sheet
A8: P25 Usage (calls/seat/month) | B8: =Assumptions!$B$23 | C8: Low-usage cohort (25th percentile)
A9: P50 Usage (calls/seat/month) | B9: =Assumptions!$B$24 | C9: Median-usage cohort (50th percentile)
A10: P75 Usage (calls/seat/month) | B10: =Assumptions!$B$25 | C10: High-usage cohort (75th percentile)
A13: SECTION B — OVERAGE REVENUE PER SEAT / MONTH | =MAX(0, Usage − Included) × Rate
A14: Metric | B14: P25 (15k calls) | C14: P50 (25k calls) | D14: P75 (40k calls) | E14: Formula (P25 shown)
A15: Usage / Seat / Month (calls) | B15: =B8 | C15: =B9 | D15: =B10 | E15: Pulls from Assumptions
A16: Included Threshold (calls) | B16: =B6 | C16: =B6 | D16: =B6 | E16: Pulls from Assumptions
A17: Overage Calls / Seat / Month | B17: =MAX(0,B15-B16) | C17: =MAX(0,C15-C16) | D17: =MAX(0,D15-D16) | E17: =MAX(0, Usage − Included)
A18: Overage Revenue / Seat / Month | B18: =B17*$B$7 | C18: =C17*$B$7 | D18: =D17*$B$7 | E18: =Overage Calls × Rate
A19: Overage Revenue / Seat / Year | B19: =B18*12 | C19: =C18*12 | D19: =D18*12 | E19: =Monthly × 12
A22: SECTION C — EXPANSION ARR BY DEAL SIZE & TIER | Seat ARR + Overage ARR
A23: Deal / Tier | B23: Seat ARR ($) | C23: P25 Overage ARR ($) | D23: P50 Overage ARR ($) | E23: P75 Overage ARR ($)
A24: ── Starter Tier ──
A25: Small (50 seats) | B25: =Assumptions!$B$14*'Tier Pricing Matrix'!$B$13*12 | C25: =Assumptions!$B$14*B19 | D25: =Assumptions!$B$14*C19 | E25: =Assumptions!$B$14*D19
A26: Mid (200 seats) | B26: =Assumptions!$B$15*'Tier Pricing Matrix'!$B$13*12 | C26: =Assumptions!$B$15*B19 | D26: =Assumptions!$B$15*C19 | E26: =Assumptions!$B$15*D19
A27: Large (500 seats) | B27: =Assumptions!$B$16*'Tier Pricing Matrix'!$B$13*12 | C27: =Assumptions!$B$16*B19 | D27: =Assumptions!$B$16*C19 | E27: =Assumptions!$B$16*D19
A29: ── Growth Tier ──
A30: Small (50 seats) | B30: =Assumptions!$B$14*'Tier Pricing Matrix'!$C$13*12 | C30: =Assumptions!$B$14*B19 | D30: =Assumptions!$B$14*C19 | E30: =Assumptions!$B$14*D19
A31: Mid (200 seats) | B31: =Assumptions!$B$15*'Tier Pricing Matrix'!$C$13*12 | C31: =Assumptions!$B$15*B19 | D31: =Assumptions!$B$15*C19 | E31: =Assumptions!$B$15*D19
A32: Large (500 seats) | B32: =Assumptions!$B$16*'Tier Pricing Matrix'!$C$13*12 | C32: =Assumptions!$B$16*B19 | D32: =Assumptions!$B$16*C19 | E32: =Assumptions!$B$16*D19
A34: ── Enterprise Tier ──
A35: Small (50 seats) | B35: =Assumptions!$B$14*'Tier Pricing Matrix'!$D$13*12 | C35: =Assumptions!$B$14*B19 | D35: =Assumptions!$B$14*C19 | E35: =Assumptions!$B$14*D19
A36: Mid (200 seats) | B36: =Assumptions!$B$15*'Tier Pricing Matrix'!$D$13*12 | C36: =Assumptions!$B$15*B19 | D36: =Assumptions!$B$15*C19 | E36: =Assumptions!$B$15*D19
A37: Large (500 seats) | B37: =Assumptions!$B$16*'Tier Pricing Matrix'!$D$13*12 | C37: =Assumptions!$B$16*B19 | D37: =Assumptions!$B$16*C19 | E37: =Assumptions!$B$16*D19
A39: SECTION D — TOTAL ARR (SEAT + OVERAGE) & EXPANSION MULTIPLIER
A40: Deal / Tier | B40: Seat ARR ($) | C40: P25 Total ARR ($) | D40: P50 Total ARR ($) | E40: P75 Total ARR ($)
A41: ── Starter Tier ──
A42: Small (50 seats) | B42: =B25 | C42: =B42+C25 | D42: =B42+D25 | E42: =B42+E25
A43: Mid (200 seats) | B43: =B26 | C43: =B43+C26 | D43: =B43+D26 | E43: =B43+E26
A44: Large (500 seats) | B44: =B27 | C44: =B44+C27 | D44: =B44+D27 | E44: =B44+E27
A45: Expansion Multiplier (Total ARR ÷ Seat ARR) | B45: 1.0x (baseline) | C45: =IFERROR(C42/B42,"-") | D45: =IFERROR(D42/B42,"-") | E45: =IFERROR(E42/B42,"-")
A47: ── Growth Tier ──
A48: Small (50 seats) | B48: =B29 | C48: =B48+C29 | D48: =B48+D29 | E48: =B48+E29
A49: Mid (200 seats) | B49: =B30 | C49: =B49+C30 | D49: =B49+D30 | E49: =B49+E30
...
